{
 "cells": [
  {
   "cell_type": "code",
   "execution_count": 2,
   "metadata": {
    "execution": {
     "iopub.execute_input": "2023-03-04T02:18:02.234513Z",
     "iopub.status.busy": "2023-03-04T02:18:02.233784Z",
     "iopub.status.idle": "2023-03-04T02:18:03.477602Z",
     "shell.execute_reply": "2023-03-04T02:18:03.475896Z",
     "shell.execute_reply.started": "2023-03-04T02:18:02.234448Z"
    }
   },
   "outputs": [],
   "source": [
    "import pandas as pd\n",
    "import numpy as np\n"
   ]
  },
  {
   "cell_type": "code",
   "execution_count": 2,
   "metadata": {},
   "outputs": [],
   "source": [
    "PCA_df = pd.read_pickle(\"../dataset/apimdsFeuturesExtracted.pickle\")"
   ]
  },
  {
   "cell_type": "code",
   "execution_count": 3,
   "metadata": {},
   "outputs": [],
   "source": [
    "df3 = pd.read_csv('../dataset/apimdsFinalissimo.csv')"
   ]
  },
  {
   "cell_type": "code",
   "execution_count": 4,
   "metadata": {},
   "outputs": [],
   "source": [
    "listToOneHot = list(df3.columns.values)\n",
    "listToOneHot.remove('malware')\n",
    "\n",
    "malwareColTrain = df3['malware'].copy()\n",
    "df3 = df3.drop('malware', axis = 1)\n",
    "\n",
    "dummyDf = pd.get_dummies(df3, listToOneHot, dummy_na=True)\n",
    "dummyDf.head(15)\n",
    "\n",
    "dummyDf.drop('116_nan', inplace=True, axis=1)"
   ]
  },
  {
   "cell_type": "code",
   "execution_count": 3,
   "metadata": {},
   "outputs": [],
   "source": [
    "#no\n",
    "from sklearn.feature_extraction import FeatureHasher\n",
    "\n",
    "malwareColTrain = df3['malware'].copy()\n",
    "df3 = df3.drop('malware', axis = 1)\n",
    "\n",
    "cols= df3.columns\n",
    "\n",
    "for c in cols:\n",
    "   fh = FeatureHasher(n_features=114, input_type='string')\n",
    "   hash_train = fh.transform(df3[[c]].astype(str).values)"
   ]
  },
  {
   "cell_type": "code",
   "execution_count": 3,
   "metadata": {},
   "outputs": [],
   "source": [
    "#no\n",
    "malwareColTrainPCA = PCA_df['malware'].copy()\n",
    "PCA_df = PCA_df.drop('malware', axis = 1)"
   ]
  },
  {
   "cell_type": "code",
   "execution_count": 4,
   "metadata": {},
   "outputs": [
    {
     "name": "stdout",
     "output_type": "stream",
     "text": [
      "precision: 0.9934\n",
      "recall: 0.9711\n",
      "f1: 0.9815\n",
      "auc_roc: 0.9711\n"
     ]
    }
   ],
   "source": [
    "from multiscorer import MultiScorer\n",
    "from sklearn.metrics import precision_score, recall_score, f1_score, roc_auc_score\n",
    "from sklearn.model_selection import cross_val_score\n",
    "from numpy import average\n",
    "from sklearn.model_selection import StratifiedKFold\n",
    "from imblearn.under_sampling import RandomUnderSampler\n",
    "from xgboost import XGBClassifier\n",
    "from imblearn.pipeline import Pipeline\n",
    "\n",
    "# define pipeline\n",
    "steps = [('under', RandomUnderSampler(sampling_strategy=0.03)), ('model', XGBClassifier(max_depth=6, learning_rate=0.3, tree_method='gpu_hist', gpu_id=1))]\n",
    "pipeline = Pipeline(steps=steps)\n",
    "cv = StratifiedKFold(n_splits=10, random_state=44, shuffle=True)\n",
    "\n",
    "scorer = MultiScorer({                                               # Create a MultiScorer instance\n",
    "    'precision': (precision_score, {'average': 'macro'}),              # Param 'average' will be passed to precision_score as kwarg \n",
    "    'recall': (recall_score, {'average': 'macro'}),\n",
    "    'f1': (f1_score, {'average': 'macro'}),\n",
    "    'auc_roc': (roc_auc_score, {'average': 'macro'})\n",
    "})\n",
    "\n",
    "\n",
    "cross_val_score(pipeline, dummyDf, malwareColTrain, scoring=scorer, cv=cv)               # Use the function with our socrer. Ignore its result \n",
    "\n",
    "results = scorer.get_results()                                       # Get a dict of lists containing the scores for each metric\n",
    "\n",
    "for metric in results.keys():                                        # Iterate and use the results\n",
    "  print(\"%s: %.4f\" % (metric, average(results[metric])))"
   ]
  },
  {
   "cell_type": "code",
   "execution_count": 5,
   "metadata": {
    "execution": {
     "iopub.execute_input": "2023-03-04T02:21:26.648062Z",
     "iopub.status.busy": "2023-03-04T02:21:26.646055Z",
     "iopub.status.idle": "2023-03-04T02:21:29.161687Z",
     "shell.execute_reply": "2023-03-04T02:21:29.160325Z",
     "shell.execute_reply.started": "2023-03-04T02:21:26.647956Z"
    }
   },
   "outputs": [
    {
     "name": "stdout",
     "output_type": "stream",
     "text": [
      "[16:48:08] ======== Monitor (0): HostSketchContainer ========\n",
      "[16:48:08] AllReduce: 0.197935s, 1 calls @ 197935us\n",
      "\n",
      "[16:48:08] MakeCuts: 0.419604s, 1 calls @ 419604us\n",
      "\n",
      "[16:48:58] ======== Monitor (0): HostSketchContainer ========\n",
      "[16:48:58] AllReduce: 0.249352s, 1 calls @ 249352us\n",
      "\n",
      "[16:48:58] MakeCuts: 0.468539s, 1 calls @ 468539us\n",
      "\n",
      "[16:49:45] ======== Monitor (0): HostSketchContainer ========\n",
      "[16:49:45] AllReduce: 0.182401s, 1 calls @ 182401us\n",
      "\n",
      "[16:49:45] MakeCuts: 0.290245s, 1 calls @ 290245us\n",
      "\n",
      "[16:50:31] ======== Monitor (0): HostSketchContainer ========\n",
      "[16:50:31] AllReduce: 0.183034s, 1 calls @ 183034us\n",
      "\n",
      "[16:50:31] MakeCuts: 0.260735s, 1 calls @ 260735us\n",
      "\n",
      "[16:51:17] ======== Monitor (0): HostSketchContainer ========\n",
      "[16:51:17] AllReduce: 0.18004s, 1 calls @ 180040us\n",
      "\n",
      "[16:51:17] MakeCuts: 0.258393s, 1 calls @ 258393us\n",
      "\n",
      "[16:52:03] ======== Monitor (0): HostSketchContainer ========\n",
      "[16:52:03] AllReduce: 0.186044s, 1 calls @ 186044us\n",
      "\n",
      "[16:52:03] MakeCuts: 0.255293s, 1 calls @ 255293us\n",
      "\n",
      "[16:52:49] ======== Monitor (0): HostSketchContainer ========\n",
      "[16:52:49] AllReduce: 0.195944s, 1 calls @ 195944us\n",
      "\n",
      "[16:52:49] MakeCuts: 0.273903s, 1 calls @ 273903us\n",
      "\n",
      "[16:53:36] ======== Monitor (0): HostSketchContainer ========\n",
      "[16:53:36] AllReduce: 0.183501s, 1 calls @ 183501us\n",
      "\n",
      "[16:53:36] MakeCuts: 0.254812s, 1 calls @ 254812us\n",
      "\n",
      "[16:54:20] ======== Monitor (0): HostSketchContainer ========\n",
      "[16:54:20] AllReduce: 0.175067s, 1 calls @ 175067us\n",
      "\n",
      "[16:54:20] MakeCuts: 0.243356s, 1 calls @ 243356us\n",
      "\n",
      "[16:55:05] ======== Monitor (0): HostSketchContainer ========\n",
      "[16:55:05] AllReduce: 0.198211s, 1 calls @ 198211us\n",
      "\n",
      "[16:55:05] MakeCuts: 0.26476s, 1 calls @ 264760us\n",
      "\n"
     ]
    },
    {
     "ename": "ValueError",
     "evalue": "\nAll the 10 fits failed.\nIt is very likely that your model is misconfigured.\nYou can try to debug the error by setting error_score='raise'.\n\nBelow are more details about the failures:\n--------------------------------------------------------------------------------\n1 fits failed with the following error:\nTraceback (most recent call last):\n  File \"/home/alessio/anaconda3/lib/python3.9/site-packages/sklearn/model_selection/_validation.py\", line 686, in _fit_and_score\n    estimator.fit(X_train, y_train, **fit_params)\n  File \"/home/alessio/anaconda3/lib/python3.9/site-packages/imblearn/pipeline.py\", line 297, in fit\n    self._final_estimator.fit(Xt, yt, **fit_params_last_step)\n  File \"/home/alessio/anaconda3/lib/python3.9/site-packages/xgboost/core.py\", line 620, in inner_f\n    return func(**kwargs)\n  File \"/home/alessio/anaconda3/lib/python3.9/site-packages/xgboost/sklearn.py\", line 1490, in fit\n    self._Booster = train(\n  File \"/home/alessio/anaconda3/lib/python3.9/site-packages/xgboost/core.py\", line 620, in inner_f\n    return func(**kwargs)\n  File \"/home/alessio/anaconda3/lib/python3.9/site-packages/xgboost/training.py\", line 185, in train\n    bst.update(dtrain, i, obj)\n  File \"/home/alessio/anaconda3/lib/python3.9/site-packages/xgboost/core.py\", line 1918, in update\n    _check_call(_LIB.XGBoosterUpdateOneIter(self.handle,\n  File \"/home/alessio/anaconda3/lib/python3.9/site-packages/xgboost/core.py\", line 279, in _check_call\n    raise XGBoostError(py_str(_LIB.XGBGetLastError()))\nxgboost.core.XGBoostError: [16:48:08] /croot/xgboost-split_1675457761144/work/src/data/../common/common.h:239: XGBoost version not compiled with GPU support.\nStack trace:\n  [bt] (0) /home/alessio/anaconda3/lib/libxgboost.so(+0xc01d4) [0x7f0fa8cc01d4]\n  [bt] (1) /home/alessio/anaconda3/lib/libxgboost.so(+0x1aaf12) [0x7f0fa8daaf12]\n  [bt] (2) /home/alessio/anaconda3/lib/libxgboost.so(xgboost::gbm::GBTree::ConfigureUpdaters()+0xdd) [0x7f0fa8e62e9d]\n  [bt] (3) /home/alessio/anaconda3/lib/libxgboost.so(xgboost::gbm::GBTree::Configure(std::vector<std::pair<std::__cxx11::basic_string<char, std::char_traits<char>, std::allocator<char> >, std::__cxx11::basic_string<char, std::char_traits<char>, std::allocator<char> > >, std::allocator<std::pair<std::__cxx11::basic_string<char, std::char_traits<char>, std::allocator<char> >, std::__cxx11::basic_string<char, std::char_traits<char>, std::allocator<char> > > > > const&)+0x331) [0x7f0fa8e7a6d1]\n  [bt] (4) /home/alessio/anaconda3/lib/libxgboost.so(+0x2a7ab2) [0x7f0fa8ea7ab2]\n  [bt] (5) /home/alessio/anaconda3/lib/libxgboost.so(+0x29f6d7) [0x7f0fa8e9f6d7]\n  [bt] (6) /home/alessio/anaconda3/lib/libxgboost.so(XGBoosterUpdateOneIter+0x6c) [0x7f0fa8ccbfbc]\n  [bt] (7) /home/alessio/anaconda3/lib/python3.9/lib-dynload/../../libffi.so.7(+0x69dd) [0x7f0fe8b059dd]\n  [bt] (8) /home/alessio/anaconda3/lib/python3.9/lib-dynload/../../libffi.so.7(+0x6067) [0x7f0fe8b05067]\n\n\n\n--------------------------------------------------------------------------------\n1 fits failed with the following error:\nTraceback (most recent call last):\n  File \"/home/alessio/anaconda3/lib/python3.9/site-packages/sklearn/model_selection/_validation.py\", line 686, in _fit_and_score\n    estimator.fit(X_train, y_train, **fit_params)\n  File \"/home/alessio/anaconda3/lib/python3.9/site-packages/imblearn/pipeline.py\", line 297, in fit\n    self._final_estimator.fit(Xt, yt, **fit_params_last_step)\n  File \"/home/alessio/anaconda3/lib/python3.9/site-packages/xgboost/core.py\", line 620, in inner_f\n    return func(**kwargs)\n  File \"/home/alessio/anaconda3/lib/python3.9/site-packages/xgboost/sklearn.py\", line 1490, in fit\n    self._Booster = train(\n  File \"/home/alessio/anaconda3/lib/python3.9/site-packages/xgboost/core.py\", line 620, in inner_f\n    return func(**kwargs)\n  File \"/home/alessio/anaconda3/lib/python3.9/site-packages/xgboost/training.py\", line 185, in train\n    bst.update(dtrain, i, obj)\n  File \"/home/alessio/anaconda3/lib/python3.9/site-packages/xgboost/core.py\", line 1918, in update\n    _check_call(_LIB.XGBoosterUpdateOneIter(self.handle,\n  File \"/home/alessio/anaconda3/lib/python3.9/site-packages/xgboost/core.py\", line 279, in _check_call\n    raise XGBoostError(py_str(_LIB.XGBGetLastError()))\nxgboost.core.XGBoostError: [16:48:59] /croot/xgboost-split_1675457761144/work/src/data/../common/common.h:239: XGBoost version not compiled with GPU support.\nStack trace:\n  [bt] (0) /home/alessio/anaconda3/lib/libxgboost.so(+0xc01d4) [0x7f0fa8cc01d4]\n  [bt] (1) /home/alessio/anaconda3/lib/libxgboost.so(+0x1aaf12) [0x7f0fa8daaf12]\n  [bt] (2) /home/alessio/anaconda3/lib/libxgboost.so(xgboost::gbm::GBTree::ConfigureUpdaters()+0xdd) [0x7f0fa8e62e9d]\n  [bt] (3) /home/alessio/anaconda3/lib/libxgboost.so(xgboost::gbm::GBTree::Configure(std::vector<std::pair<std::__cxx11::basic_string<char, std::char_traits<char>, std::allocator<char> >, std::__cxx11::basic_string<char, std::char_traits<char>, std::allocator<char> > >, std::allocator<std::pair<std::__cxx11::basic_string<char, std::char_traits<char>, std::allocator<char> >, std::__cxx11::basic_string<char, std::char_traits<char>, std::allocator<char> > > > > const&)+0x331) [0x7f0fa8e7a6d1]\n  [bt] (4) /home/alessio/anaconda3/lib/libxgboost.so(+0x2a7ab2) [0x7f0fa8ea7ab2]\n  [bt] (5) /home/alessio/anaconda3/lib/libxgboost.so(+0x29f6d7) [0x7f0fa8e9f6d7]\n  [bt] (6) /home/alessio/anaconda3/lib/libxgboost.so(XGBoosterUpdateOneIter+0x6c) [0x7f0fa8ccbfbc]\n  [bt] (7) /home/alessio/anaconda3/lib/python3.9/lib-dynload/../../libffi.so.7(+0x69dd) [0x7f0fe8b059dd]\n  [bt] (8) /home/alessio/anaconda3/lib/python3.9/lib-dynload/../../libffi.so.7(+0x6067) [0x7f0fe8b05067]\n\n\n\n--------------------------------------------------------------------------------\n1 fits failed with the following error:\nTraceback (most recent call last):\n  File \"/home/alessio/anaconda3/lib/python3.9/site-packages/sklearn/model_selection/_validation.py\", line 686, in _fit_and_score\n    estimator.fit(X_train, y_train, **fit_params)\n  File \"/home/alessio/anaconda3/lib/python3.9/site-packages/imblearn/pipeline.py\", line 297, in fit\n    self._final_estimator.fit(Xt, yt, **fit_params_last_step)\n  File \"/home/alessio/anaconda3/lib/python3.9/site-packages/xgboost/core.py\", line 620, in inner_f\n    return func(**kwargs)\n  File \"/home/alessio/anaconda3/lib/python3.9/site-packages/xgboost/sklearn.py\", line 1490, in fit\n    self._Booster = train(\n  File \"/home/alessio/anaconda3/lib/python3.9/site-packages/xgboost/core.py\", line 620, in inner_f\n    return func(**kwargs)\n  File \"/home/alessio/anaconda3/lib/python3.9/site-packages/xgboost/training.py\", line 185, in train\n    bst.update(dtrain, i, obj)\n  File \"/home/alessio/anaconda3/lib/python3.9/site-packages/xgboost/core.py\", line 1918, in update\n    _check_call(_LIB.XGBoosterUpdateOneIter(self.handle,\n  File \"/home/alessio/anaconda3/lib/python3.9/site-packages/xgboost/core.py\", line 279, in _check_call\n    raise XGBoostError(py_str(_LIB.XGBGetLastError()))\nxgboost.core.XGBoostError: [16:49:45] /croot/xgboost-split_1675457761144/work/src/data/../common/common.h:239: XGBoost version not compiled with GPU support.\nStack trace:\n  [bt] (0) /home/alessio/anaconda3/lib/libxgboost.so(+0xc01d4) [0x7f0fa8cc01d4]\n  [bt] (1) /home/alessio/anaconda3/lib/libxgboost.so(+0x1aaf12) [0x7f0fa8daaf12]\n  [bt] (2) /home/alessio/anaconda3/lib/libxgboost.so(xgboost::gbm::GBTree::ConfigureUpdaters()+0xdd) [0x7f0fa8e62e9d]\n  [bt] (3) /home/alessio/anaconda3/lib/libxgboost.so(xgboost::gbm::GBTree::Configure(std::vector<std::pair<std::__cxx11::basic_string<char, std::char_traits<char>, std::allocator<char> >, std::__cxx11::basic_string<char, std::char_traits<char>, std::allocator<char> > >, std::allocator<std::pair<std::__cxx11::basic_string<char, std::char_traits<char>, std::allocator<char> >, std::__cxx11::basic_string<char, std::char_traits<char>, std::allocator<char> > > > > const&)+0x331) [0x7f0fa8e7a6d1]\n  [bt] (4) /home/alessio/anaconda3/lib/libxgboost.so(+0x2a7ab2) [0x7f0fa8ea7ab2]\n  [bt] (5) /home/alessio/anaconda3/lib/libxgboost.so(+0x29f6d7) [0x7f0fa8e9f6d7]\n  [bt] (6) /home/alessio/anaconda3/lib/libxgboost.so(XGBoosterUpdateOneIter+0x6c) [0x7f0fa8ccbfbc]\n  [bt] (7) /home/alessio/anaconda3/lib/python3.9/lib-dynload/../../libffi.so.7(+0x69dd) [0x7f0fe8b059dd]\n  [bt] (8) /home/alessio/anaconda3/lib/python3.9/lib-dynload/../../libffi.so.7(+0x6067) [0x7f0fe8b05067]\n\n\n\n--------------------------------------------------------------------------------\n1 fits failed with the following error:\nTraceback (most recent call last):\n  File \"/home/alessio/anaconda3/lib/python3.9/site-packages/sklearn/model_selection/_validation.py\", line 686, in _fit_and_score\n    estimator.fit(X_train, y_train, **fit_params)\n  File \"/home/alessio/anaconda3/lib/python3.9/site-packages/imblearn/pipeline.py\", line 297, in fit\n    self._final_estimator.fit(Xt, yt, **fit_params_last_step)\n  File \"/home/alessio/anaconda3/lib/python3.9/site-packages/xgboost/core.py\", line 620, in inner_f\n    return func(**kwargs)\n  File \"/home/alessio/anaconda3/lib/python3.9/site-packages/xgboost/sklearn.py\", line 1490, in fit\n    self._Booster = train(\n  File \"/home/alessio/anaconda3/lib/python3.9/site-packages/xgboost/core.py\", line 620, in inner_f\n    return func(**kwargs)\n  File \"/home/alessio/anaconda3/lib/python3.9/site-packages/xgboost/training.py\", line 185, in train\n    bst.update(dtrain, i, obj)\n  File \"/home/alessio/anaconda3/lib/python3.9/site-packages/xgboost/core.py\", line 1918, in update\n    _check_call(_LIB.XGBoosterUpdateOneIter(self.handle,\n  File \"/home/alessio/anaconda3/lib/python3.9/site-packages/xgboost/core.py\", line 279, in _check_call\n    raise XGBoostError(py_str(_LIB.XGBGetLastError()))\nxgboost.core.XGBoostError: [16:50:31] /croot/xgboost-split_1675457761144/work/src/data/../common/common.h:239: XGBoost version not compiled with GPU support.\nStack trace:\n  [bt] (0) /home/alessio/anaconda3/lib/libxgboost.so(+0xc01d4) [0x7f0fa8cc01d4]\n  [bt] (1) /home/alessio/anaconda3/lib/libxgboost.so(+0x1aaf12) [0x7f0fa8daaf12]\n  [bt] (2) /home/alessio/anaconda3/lib/libxgboost.so(xgboost::gbm::GBTree::ConfigureUpdaters()+0xdd) [0x7f0fa8e62e9d]\n  [bt] (3) /home/alessio/anaconda3/lib/libxgboost.so(xgboost::gbm::GBTree::Configure(std::vector<std::pair<std::__cxx11::basic_string<char, std::char_traits<char>, std::allocator<char> >, std::__cxx11::basic_string<char, std::char_traits<char>, std::allocator<char> > >, std::allocator<std::pair<std::__cxx11::basic_string<char, std::char_traits<char>, std::allocator<char> >, std::__cxx11::basic_string<char, std::char_traits<char>, std::allocator<char> > > > > const&)+0x331) [0x7f0fa8e7a6d1]\n  [bt] (4) /home/alessio/anaconda3/lib/libxgboost.so(+0x2a7ab2) [0x7f0fa8ea7ab2]\n  [bt] (5) /home/alessio/anaconda3/lib/libxgboost.so(+0x29f6d7) [0x7f0fa8e9f6d7]\n  [bt] (6) /home/alessio/anaconda3/lib/libxgboost.so(XGBoosterUpdateOneIter+0x6c) [0x7f0fa8ccbfbc]\n  [bt] (7) /home/alessio/anaconda3/lib/python3.9/lib-dynload/../../libffi.so.7(+0x69dd) [0x7f0fe8b059dd]\n  [bt] (8) /home/alessio/anaconda3/lib/python3.9/lib-dynload/../../libffi.so.7(+0x6067) [0x7f0fe8b05067]\n\n\n\n--------------------------------------------------------------------------------\n1 fits failed with the following error:\nTraceback (most recent call last):\n  File \"/home/alessio/anaconda3/lib/python3.9/site-packages/sklearn/model_selection/_validation.py\", line 686, in _fit_and_score\n    estimator.fit(X_train, y_train, **fit_params)\n  File \"/home/alessio/anaconda3/lib/python3.9/site-packages/imblearn/pipeline.py\", line 297, in fit\n    self._final_estimator.fit(Xt, yt, **fit_params_last_step)\n  File \"/home/alessio/anaconda3/lib/python3.9/site-packages/xgboost/core.py\", line 620, in inner_f\n    return func(**kwargs)\n  File \"/home/alessio/anaconda3/lib/python3.9/site-packages/xgboost/sklearn.py\", line 1490, in fit\n    self._Booster = train(\n  File \"/home/alessio/anaconda3/lib/python3.9/site-packages/xgboost/core.py\", line 620, in inner_f\n    return func(**kwargs)\n  File \"/home/alessio/anaconda3/lib/python3.9/site-packages/xgboost/training.py\", line 185, in train\n    bst.update(dtrain, i, obj)\n  File \"/home/alessio/anaconda3/lib/python3.9/site-packages/xgboost/core.py\", line 1918, in update\n    _check_call(_LIB.XGBoosterUpdateOneIter(self.handle,\n  File \"/home/alessio/anaconda3/lib/python3.9/site-packages/xgboost/core.py\", line 279, in _check_call\n    raise XGBoostError(py_str(_LIB.XGBGetLastError()))\nxgboost.core.XGBoostError: [16:51:18] /croot/xgboost-split_1675457761144/work/src/data/../common/common.h:239: XGBoost version not compiled with GPU support.\nStack trace:\n  [bt] (0) /home/alessio/anaconda3/lib/libxgboost.so(+0xc01d4) [0x7f0fa8cc01d4]\n  [bt] (1) /home/alessio/anaconda3/lib/libxgboost.so(+0x1aaf12) [0x7f0fa8daaf12]\n  [bt] (2) /home/alessio/anaconda3/lib/libxgboost.so(xgboost::gbm::GBTree::ConfigureUpdaters()+0xdd) [0x7f0fa8e62e9d]\n  [bt] (3) /home/alessio/anaconda3/lib/libxgboost.so(xgboost::gbm::GBTree::Configure(std::vector<std::pair<std::__cxx11::basic_string<char, std::char_traits<char>, std::allocator<char> >, std::__cxx11::basic_string<char, std::char_traits<char>, std::allocator<char> > >, std::allocator<std::pair<std::__cxx11::basic_string<char, std::char_traits<char>, std::allocator<char> >, std::__cxx11::basic_string<char, std::char_traits<char>, std::allocator<char> > > > > const&)+0x331) [0x7f0fa8e7a6d1]\n  [bt] (4) /home/alessio/anaconda3/lib/libxgboost.so(+0x2a7ab2) [0x7f0fa8ea7ab2]\n  [bt] (5) /home/alessio/anaconda3/lib/libxgboost.so(+0x29f6d7) [0x7f0fa8e9f6d7]\n  [bt] (6) /home/alessio/anaconda3/lib/libxgboost.so(XGBoosterUpdateOneIter+0x6c) [0x7f0fa8ccbfbc]\n  [bt] (7) /home/alessio/anaconda3/lib/python3.9/lib-dynload/../../libffi.so.7(+0x69dd) [0x7f0fe8b059dd]\n  [bt] (8) /home/alessio/anaconda3/lib/python3.9/lib-dynload/../../libffi.so.7(+0x6067) [0x7f0fe8b05067]\n\n\n\n--------------------------------------------------------------------------------\n1 fits failed with the following error:\nTraceback (most recent call last):\n  File \"/home/alessio/anaconda3/lib/python3.9/site-packages/sklearn/model_selection/_validation.py\", line 686, in _fit_and_score\n    estimator.fit(X_train, y_train, **fit_params)\n  File \"/home/alessio/anaconda3/lib/python3.9/site-packages/imblearn/pipeline.py\", line 297, in fit\n    self._final_estimator.fit(Xt, yt, **fit_params_last_step)\n  File \"/home/alessio/anaconda3/lib/python3.9/site-packages/xgboost/core.py\", line 620, in inner_f\n    return func(**kwargs)\n  File \"/home/alessio/anaconda3/lib/python3.9/site-packages/xgboost/sklearn.py\", line 1490, in fit\n    self._Booster = train(\n  File \"/home/alessio/anaconda3/lib/python3.9/site-packages/xgboost/core.py\", line 620, in inner_f\n    return func(**kwargs)\n  File \"/home/alessio/anaconda3/lib/python3.9/site-packages/xgboost/training.py\", line 185, in train\n    bst.update(dtrain, i, obj)\n  File \"/home/alessio/anaconda3/lib/python3.9/site-packages/xgboost/core.py\", line 1918, in update\n    _check_call(_LIB.XGBoosterUpdateOneIter(self.handle,\n  File \"/home/alessio/anaconda3/lib/python3.9/site-packages/xgboost/core.py\", line 279, in _check_call\n    raise XGBoostError(py_str(_LIB.XGBGetLastError()))\nxgboost.core.XGBoostError: [16:52:04] /croot/xgboost-split_1675457761144/work/src/data/../common/common.h:239: XGBoost version not compiled with GPU support.\nStack trace:\n  [bt] (0) /home/alessio/anaconda3/lib/libxgboost.so(+0xc01d4) [0x7f0fa8cc01d4]\n  [bt] (1) /home/alessio/anaconda3/lib/libxgboost.so(+0x1aaf12) [0x7f0fa8daaf12]\n  [bt] (2) /home/alessio/anaconda3/lib/libxgboost.so(xgboost::gbm::GBTree::ConfigureUpdaters()+0xdd) [0x7f0fa8e62e9d]\n  [bt] (3) /home/alessio/anaconda3/lib/libxgboost.so(xgboost::gbm::GBTree::Configure(std::vector<std::pair<std::__cxx11::basic_string<char, std::char_traits<char>, std::allocator<char> >, std::__cxx11::basic_string<char, std::char_traits<char>, std::allocator<char> > >, std::allocator<std::pair<std::__cxx11::basic_string<char, std::char_traits<char>, std::allocator<char> >, std::__cxx11::basic_string<char, std::char_traits<char>, std::allocator<char> > > > > const&)+0x331) [0x7f0fa8e7a6d1]\n  [bt] (4) /home/alessio/anaconda3/lib/libxgboost.so(+0x2a7ab2) [0x7f0fa8ea7ab2]\n  [bt] (5) /home/alessio/anaconda3/lib/libxgboost.so(+0x29f6d7) [0x7f0fa8e9f6d7]\n  [bt] (6) /home/alessio/anaconda3/lib/libxgboost.so(XGBoosterUpdateOneIter+0x6c) [0x7f0fa8ccbfbc]\n  [bt] (7) /home/alessio/anaconda3/lib/python3.9/lib-dynload/../../libffi.so.7(+0x69dd) [0x7f0fe8b059dd]\n  [bt] (8) /home/alessio/anaconda3/lib/python3.9/lib-dynload/../../libffi.so.7(+0x6067) [0x7f0fe8b05067]\n\n\n\n--------------------------------------------------------------------------------\n1 fits failed with the following error:\nTraceback (most recent call last):\n  File \"/home/alessio/anaconda3/lib/python3.9/site-packages/sklearn/model_selection/_validation.py\", line 686, in _fit_and_score\n    estimator.fit(X_train, y_train, **fit_params)\n  File \"/home/alessio/anaconda3/lib/python3.9/site-packages/imblearn/pipeline.py\", line 297, in fit\n    self._final_estimator.fit(Xt, yt, **fit_params_last_step)\n  File \"/home/alessio/anaconda3/lib/python3.9/site-packages/xgboost/core.py\", line 620, in inner_f\n    return func(**kwargs)\n  File \"/home/alessio/anaconda3/lib/python3.9/site-packages/xgboost/sklearn.py\", line 1490, in fit\n    self._Booster = train(\n  File \"/home/alessio/anaconda3/lib/python3.9/site-packages/xgboost/core.py\", line 620, in inner_f\n    return func(**kwargs)\n  File \"/home/alessio/anaconda3/lib/python3.9/site-packages/xgboost/training.py\", line 185, in train\n    bst.update(dtrain, i, obj)\n  File \"/home/alessio/anaconda3/lib/python3.9/site-packages/xgboost/core.py\", line 1918, in update\n    _check_call(_LIB.XGBoosterUpdateOneIter(self.handle,\n  File \"/home/alessio/anaconda3/lib/python3.9/site-packages/xgboost/core.py\", line 279, in _check_call\n    raise XGBoostError(py_str(_LIB.XGBGetLastError()))\nxgboost.core.XGBoostError: [16:52:50] /croot/xgboost-split_1675457761144/work/src/data/../common/common.h:239: XGBoost version not compiled with GPU support.\nStack trace:\n  [bt] (0) /home/alessio/anaconda3/lib/libxgboost.so(+0xc01d4) [0x7f0fa8cc01d4]\n  [bt] (1) /home/alessio/anaconda3/lib/libxgboost.so(+0x1aaf12) [0x7f0fa8daaf12]\n  [bt] (2) /home/alessio/anaconda3/lib/libxgboost.so(xgboost::gbm::GBTree::ConfigureUpdaters()+0xdd) [0x7f0fa8e62e9d]\n  [bt] (3) /home/alessio/anaconda3/lib/libxgboost.so(xgboost::gbm::GBTree::Configure(std::vector<std::pair<std::__cxx11::basic_string<char, std::char_traits<char>, std::allocator<char> >, std::__cxx11::basic_string<char, std::char_traits<char>, std::allocator<char> > >, std::allocator<std::pair<std::__cxx11::basic_string<char, std::char_traits<char>, std::allocator<char> >, std::__cxx11::basic_string<char, std::char_traits<char>, std::allocator<char> > > > > const&)+0x331) [0x7f0fa8e7a6d1]\n  [bt] (4) /home/alessio/anaconda3/lib/libxgboost.so(+0x2a7ab2) [0x7f0fa8ea7ab2]\n  [bt] (5) /home/alessio/anaconda3/lib/libxgboost.so(+0x29f6d7) [0x7f0fa8e9f6d7]\n  [bt] (6) /home/alessio/anaconda3/lib/libxgboost.so(XGBoosterUpdateOneIter+0x6c) [0x7f0fa8ccbfbc]\n  [bt] (7) /home/alessio/anaconda3/lib/python3.9/lib-dynload/../../libffi.so.7(+0x69dd) [0x7f0fe8b059dd]\n  [bt] (8) /home/alessio/anaconda3/lib/python3.9/lib-dynload/../../libffi.so.7(+0x6067) [0x7f0fe8b05067]\n\n\n\n--------------------------------------------------------------------------------\n1 fits failed with the following error:\nTraceback (most recent call last):\n  File \"/home/alessio/anaconda3/lib/python3.9/site-packages/sklearn/model_selection/_validation.py\", line 686, in _fit_and_score\n    estimator.fit(X_train, y_train, **fit_params)\n  File \"/home/alessio/anaconda3/lib/python3.9/site-packages/imblearn/pipeline.py\", line 297, in fit\n    self._final_estimator.fit(Xt, yt, **fit_params_last_step)\n  File \"/home/alessio/anaconda3/lib/python3.9/site-packages/xgboost/core.py\", line 620, in inner_f\n    return func(**kwargs)\n  File \"/home/alessio/anaconda3/lib/python3.9/site-packages/xgboost/sklearn.py\", line 1490, in fit\n    self._Booster = train(\n  File \"/home/alessio/anaconda3/lib/python3.9/site-packages/xgboost/core.py\", line 620, in inner_f\n    return func(**kwargs)\n  File \"/home/alessio/anaconda3/lib/python3.9/site-packages/xgboost/training.py\", line 185, in train\n    bst.update(dtrain, i, obj)\n  File \"/home/alessio/anaconda3/lib/python3.9/site-packages/xgboost/core.py\", line 1918, in update\n    _check_call(_LIB.XGBoosterUpdateOneIter(self.handle,\n  File \"/home/alessio/anaconda3/lib/python3.9/site-packages/xgboost/core.py\", line 279, in _check_call\n    raise XGBoostError(py_str(_LIB.XGBGetLastError()))\nxgboost.core.XGBoostError: [16:53:36] /croot/xgboost-split_1675457761144/work/src/data/../common/common.h:239: XGBoost version not compiled with GPU support.\nStack trace:\n  [bt] (0) /home/alessio/anaconda3/lib/libxgboost.so(+0xc01d4) [0x7f0fa8cc01d4]\n  [bt] (1) /home/alessio/anaconda3/lib/libxgboost.so(+0x1aaf12) [0x7f0fa8daaf12]\n  [bt] (2) /home/alessio/anaconda3/lib/libxgboost.so(xgboost::gbm::GBTree::ConfigureUpdaters()+0xdd) [0x7f0fa8e62e9d]\n  [bt] (3) /home/alessio/anaconda3/lib/libxgboost.so(xgboost::gbm::GBTree::Configure(std::vector<std::pair<std::__cxx11::basic_string<char, std::char_traits<char>, std::allocator<char> >, std::__cxx11::basic_string<char, std::char_traits<char>, std::allocator<char> > >, std::allocator<std::pair<std::__cxx11::basic_string<char, std::char_traits<char>, std::allocator<char> >, std::__cxx11::basic_string<char, std::char_traits<char>, std::allocator<char> > > > > const&)+0x331) [0x7f0fa8e7a6d1]\n  [bt] (4) /home/alessio/anaconda3/lib/libxgboost.so(+0x2a7ab2) [0x7f0fa8ea7ab2]\n  [bt] (5) /home/alessio/anaconda3/lib/libxgboost.so(+0x29f6d7) [0x7f0fa8e9f6d7]\n  [bt] (6) /home/alessio/anaconda3/lib/libxgboost.so(XGBoosterUpdateOneIter+0x6c) [0x7f0fa8ccbfbc]\n  [bt] (7) /home/alessio/anaconda3/lib/python3.9/lib-dynload/../../libffi.so.7(+0x69dd) [0x7f0fe8b059dd]\n  [bt] (8) /home/alessio/anaconda3/lib/python3.9/lib-dynload/../../libffi.so.7(+0x6067) [0x7f0fe8b05067]\n\n\n\n--------------------------------------------------------------------------------\n1 fits failed with the following error:\nTraceback (most recent call last):\n  File \"/home/alessio/anaconda3/lib/python3.9/site-packages/sklearn/model_selection/_validation.py\", line 686, in _fit_and_score\n    estimator.fit(X_train, y_train, **fit_params)\n  File \"/home/alessio/anaconda3/lib/python3.9/site-packages/imblearn/pipeline.py\", line 297, in fit\n    self._final_estimator.fit(Xt, yt, **fit_params_last_step)\n  File \"/home/alessio/anaconda3/lib/python3.9/site-packages/xgboost/core.py\", line 620, in inner_f\n    return func(**kwargs)\n  File \"/home/alessio/anaconda3/lib/python3.9/site-packages/xgboost/sklearn.py\", line 1490, in fit\n    self._Booster = train(\n  File \"/home/alessio/anaconda3/lib/python3.9/site-packages/xgboost/core.py\", line 620, in inner_f\n    return func(**kwargs)\n  File \"/home/alessio/anaconda3/lib/python3.9/site-packages/xgboost/training.py\", line 185, in train\n    bst.update(dtrain, i, obj)\n  File \"/home/alessio/anaconda3/lib/python3.9/site-packages/xgboost/core.py\", line 1918, in update\n    _check_call(_LIB.XGBoosterUpdateOneIter(self.handle,\n  File \"/home/alessio/anaconda3/lib/python3.9/site-packages/xgboost/core.py\", line 279, in _check_call\n    raise XGBoostError(py_str(_LIB.XGBGetLastError()))\nxgboost.core.XGBoostError: [16:54:21] /croot/xgboost-split_1675457761144/work/src/data/../common/common.h:239: XGBoost version not compiled with GPU support.\nStack trace:\n  [bt] (0) /home/alessio/anaconda3/lib/libxgboost.so(+0xc01d4) [0x7f0fa8cc01d4]\n  [bt] (1) /home/alessio/anaconda3/lib/libxgboost.so(+0x1aaf12) [0x7f0fa8daaf12]\n  [bt] (2) /home/alessio/anaconda3/lib/libxgboost.so(xgboost::gbm::GBTree::ConfigureUpdaters()+0xdd) [0x7f0fa8e62e9d]\n  [bt] (3) /home/alessio/anaconda3/lib/libxgboost.so(xgboost::gbm::GBTree::Configure(std::vector<std::pair<std::__cxx11::basic_string<char, std::char_traits<char>, std::allocator<char> >, std::__cxx11::basic_string<char, std::char_traits<char>, std::allocator<char> > >, std::allocator<std::pair<std::__cxx11::basic_string<char, std::char_traits<char>, std::allocator<char> >, std::__cxx11::basic_string<char, std::char_traits<char>, std::allocator<char> > > > > const&)+0x331) [0x7f0fa8e7a6d1]\n  [bt] (4) /home/alessio/anaconda3/lib/libxgboost.so(+0x2a7ab2) [0x7f0fa8ea7ab2]\n  [bt] (5) /home/alessio/anaconda3/lib/libxgboost.so(+0x29f6d7) [0x7f0fa8e9f6d7]\n  [bt] (6) /home/alessio/anaconda3/lib/libxgboost.so(XGBoosterUpdateOneIter+0x6c) [0x7f0fa8ccbfbc]\n  [bt] (7) /home/alessio/anaconda3/lib/python3.9/lib-dynload/../../libffi.so.7(+0x69dd) [0x7f0fe8b059dd]\n  [bt] (8) /home/alessio/anaconda3/lib/python3.9/lib-dynload/../../libffi.so.7(+0x6067) [0x7f0fe8b05067]\n\n\n\n--------------------------------------------------------------------------------\n1 fits failed with the following error:\nTraceback (most recent call last):\n  File \"/home/alessio/anaconda3/lib/python3.9/site-packages/sklearn/model_selection/_validation.py\", line 686, in _fit_and_score\n    estimator.fit(X_train, y_train, **fit_params)\n  File \"/home/alessio/anaconda3/lib/python3.9/site-packages/imblearn/pipeline.py\", line 297, in fit\n    self._final_estimator.fit(Xt, yt, **fit_params_last_step)\n  File \"/home/alessio/anaconda3/lib/python3.9/site-packages/xgboost/core.py\", line 620, in inner_f\n    return func(**kwargs)\n  File \"/home/alessio/anaconda3/lib/python3.9/site-packages/xgboost/sklearn.py\", line 1490, in fit\n    self._Booster = train(\n  File \"/home/alessio/anaconda3/lib/python3.9/site-packages/xgboost/core.py\", line 620, in inner_f\n    return func(**kwargs)\n  File \"/home/alessio/anaconda3/lib/python3.9/site-packages/xgboost/training.py\", line 185, in train\n    bst.update(dtrain, i, obj)\n  File \"/home/alessio/anaconda3/lib/python3.9/site-packages/xgboost/core.py\", line 1918, in update\n    _check_call(_LIB.XGBoosterUpdateOneIter(self.handle,\n  File \"/home/alessio/anaconda3/lib/python3.9/site-packages/xgboost/core.py\", line 279, in _check_call\n    raise XGBoostError(py_str(_LIB.XGBGetLastError()))\nxgboost.core.XGBoostError: [16:55:05] /croot/xgboost-split_1675457761144/work/src/data/../common/common.h:239: XGBoost version not compiled with GPU support.\nStack trace:\n  [bt] (0) /home/alessio/anaconda3/lib/libxgboost.so(+0xc01d4) [0x7f0fa8cc01d4]\n  [bt] (1) /home/alessio/anaconda3/lib/libxgboost.so(+0x1aaf12) [0x7f0fa8daaf12]\n  [bt] (2) /home/alessio/anaconda3/lib/libxgboost.so(xgboost::gbm::GBTree::ConfigureUpdaters()+0xdd) [0x7f0fa8e62e9d]\n  [bt] (3) /home/alessio/anaconda3/lib/libxgboost.so(xgboost::gbm::GBTree::Configure(std::vector<std::pair<std::__cxx11::basic_string<char, std::char_traits<char>, std::allocator<char> >, std::__cxx11::basic_string<char, std::char_traits<char>, std::allocator<char> > >, std::allocator<std::pair<std::__cxx11::basic_string<char, std::char_traits<char>, std::allocator<char> >, std::__cxx11::basic_string<char, std::char_traits<char>, std::allocator<char> > > > > const&)+0x331) [0x7f0fa8e7a6d1]\n  [bt] (4) /home/alessio/anaconda3/lib/libxgboost.so(+0x2a7ab2) [0x7f0fa8ea7ab2]\n  [bt] (5) /home/alessio/anaconda3/lib/libxgboost.so(+0x29f6d7) [0x7f0fa8e9f6d7]\n  [bt] (6) /home/alessio/anaconda3/lib/libxgboost.so(XGBoosterUpdateOneIter+0x6c) [0x7f0fa8ccbfbc]\n  [bt] (7) /home/alessio/anaconda3/lib/python3.9/lib-dynload/../../libffi.so.7(+0x69dd) [0x7f0fe8b059dd]\n  [bt] (8) /home/alessio/anaconda3/lib/python3.9/lib-dynload/../../libffi.so.7(+0x6067) [0x7f0fe8b05067]\n\n\n",
     "output_type": "error",
     "traceback": [
      "\u001b[0;31m---------------------------------------------------------------------------\u001b[0m",
      "\u001b[0;31mValueError\u001b[0m                                Traceback (most recent call last)",
      "\u001b[0;32m/tmp/ipykernel_21377/2908715264.py\u001b[0m in \u001b[0;36m<module>\u001b[0;34m\u001b[0m\n\u001b[1;32m     12\u001b[0m \u001b[0mscoring\u001b[0m \u001b[0;34m=\u001b[0m \u001b[0;34m[\u001b[0m\u001b[0;34m'precision_macro'\u001b[0m\u001b[0;34m,\u001b[0m \u001b[0;34m'recall_macro'\u001b[0m\u001b[0;34m,\u001b[0m \u001b[0;34m'f1_macro'\u001b[0m\u001b[0;34m,\u001b[0m \u001b[0;34m'roc_auc'\u001b[0m\u001b[0;34m]\u001b[0m\u001b[0;34m\u001b[0m\u001b[0;34m\u001b[0m\u001b[0m\n\u001b[1;32m     13\u001b[0m \u001b[0mcv\u001b[0m \u001b[0;34m=\u001b[0m \u001b[0mStratifiedKFold\u001b[0m\u001b[0;34m(\u001b[0m\u001b[0mn_splits\u001b[0m\u001b[0;34m=\u001b[0m\u001b[0;36m10\u001b[0m\u001b[0;34m,\u001b[0m \u001b[0mrandom_state\u001b[0m\u001b[0;34m=\u001b[0m\u001b[0;36m42\u001b[0m\u001b[0;34m,\u001b[0m \u001b[0mshuffle\u001b[0m\u001b[0;34m=\u001b[0m\u001b[0;32mTrue\u001b[0m\u001b[0;34m)\u001b[0m\u001b[0;34m\u001b[0m\u001b[0;34m\u001b[0m\u001b[0m\n\u001b[0;32m---> 14\u001b[0;31m \u001b[0mscores\u001b[0m \u001b[0;34m=\u001b[0m \u001b[0mcross_validate\u001b[0m\u001b[0;34m(\u001b[0m\u001b[0mpipeline\u001b[0m\u001b[0;34m,\u001b[0m \u001b[0mdummyDf\u001b[0m\u001b[0;34m,\u001b[0m \u001b[0mmalwareColTrain\u001b[0m\u001b[0;34m,\u001b[0m \u001b[0mscoring\u001b[0m\u001b[0;34m=\u001b[0m\u001b[0mscoring\u001b[0m\u001b[0;34m,\u001b[0m \u001b[0mcv\u001b[0m\u001b[0;34m=\u001b[0m\u001b[0mcv\u001b[0m\u001b[0;34m)\u001b[0m\u001b[0;34m\u001b[0m\u001b[0;34m\u001b[0m\u001b[0m\n\u001b[0m\u001b[1;32m     15\u001b[0m \u001b[0;34m\u001b[0m\u001b[0m\n",
      "\u001b[0;32m~/anaconda3/lib/python3.9/site-packages/sklearn/model_selection/_validation.py\u001b[0m in \u001b[0;36mcross_validate\u001b[0;34m(estimator, X, y, groups, scoring, cv, n_jobs, verbose, fit_params, pre_dispatch, return_train_score, return_estimator, error_score)\u001b[0m\n\u001b[1;32m    283\u001b[0m     )\n\u001b[1;32m    284\u001b[0m \u001b[0;34m\u001b[0m\u001b[0m\n\u001b[0;32m--> 285\u001b[0;31m     \u001b[0m_warn_or_raise_about_fit_failures\u001b[0m\u001b[0;34m(\u001b[0m\u001b[0mresults\u001b[0m\u001b[0;34m,\u001b[0m \u001b[0merror_score\u001b[0m\u001b[0;34m)\u001b[0m\u001b[0;34m\u001b[0m\u001b[0;34m\u001b[0m\u001b[0m\n\u001b[0m\u001b[1;32m    286\u001b[0m \u001b[0;34m\u001b[0m\u001b[0m\n\u001b[1;32m    287\u001b[0m     \u001b[0;31m# For callabe scoring, the return type is only know after calling. If the\u001b[0m\u001b[0;34m\u001b[0m\u001b[0;34m\u001b[0m\u001b[0m\n",
      "\u001b[0;32m~/anaconda3/lib/python3.9/site-packages/sklearn/model_selection/_validation.py\u001b[0m in \u001b[0;36m_warn_or_raise_about_fit_failures\u001b[0;34m(results, error_score)\u001b[0m\n\u001b[1;32m    365\u001b[0m                 \u001b[0;34mf\"Below are more details about the failures:\\n{fit_errors_summary}\"\u001b[0m\u001b[0;34m\u001b[0m\u001b[0;34m\u001b[0m\u001b[0m\n\u001b[1;32m    366\u001b[0m             )\n\u001b[0;32m--> 367\u001b[0;31m             \u001b[0;32mraise\u001b[0m \u001b[0mValueError\u001b[0m\u001b[0;34m(\u001b[0m\u001b[0mall_fits_failed_message\u001b[0m\u001b[0;34m)\u001b[0m\u001b[0;34m\u001b[0m\u001b[0;34m\u001b[0m\u001b[0m\n\u001b[0m\u001b[1;32m    368\u001b[0m \u001b[0;34m\u001b[0m\u001b[0m\n\u001b[1;32m    369\u001b[0m         \u001b[0;32melse\u001b[0m\u001b[0;34m:\u001b[0m\u001b[0;34m\u001b[0m\u001b[0;34m\u001b[0m\u001b[0m\n",
      "\u001b[0;31mValueError\u001b[0m: \nAll the 10 fits failed.\nIt is very likely that your model is misconfigured.\nYou can try to debug the error by setting error_score='raise'.\n\nBelow are more details about the failures:\n--------------------------------------------------------------------------------\n1 fits failed with the following error:\nTraceback (most recent call last):\n  File \"/home/alessio/anaconda3/lib/python3.9/site-packages/sklearn/model_selection/_validation.py\", line 686, in _fit_and_score\n    estimator.fit(X_train, y_train, **fit_params)\n  File \"/home/alessio/anaconda3/lib/python3.9/site-packages/imblearn/pipeline.py\", line 297, in fit\n    self._final_estimator.fit(Xt, yt, **fit_params_last_step)\n  File \"/home/alessio/anaconda3/lib/python3.9/site-packages/xgboost/core.py\", line 620, in inner_f\n    return func(**kwargs)\n  File \"/home/alessio/anaconda3/lib/python3.9/site-packages/xgboost/sklearn.py\", line 1490, in fit\n    self._Booster = train(\n  File \"/home/alessio/anaconda3/lib/python3.9/site-packages/xgboost/core.py\", line 620, in inner_f\n    return func(**kwargs)\n  File \"/home/alessio/anaconda3/lib/python3.9/site-packages/xgboost/training.py\", line 185, in train\n    bst.update(dtrain, i, obj)\n  File \"/home/alessio/anaconda3/lib/python3.9/site-packages/xgboost/core.py\", line 1918, in update\n    _check_call(_LIB.XGBoosterUpdateOneIter(self.handle,\n  File \"/home/alessio/anaconda3/lib/python3.9/site-packages/xgboost/core.py\", line 279, in _check_call\n    raise XGBoostError(py_str(_LIB.XGBGetLastError()))\nxgboost.core.XGBoostError: [16:48:08] /croot/xgboost-split_1675457761144/work/src/data/../common/common.h:239: XGBoost version not compiled with GPU support.\nStack trace:\n  [bt] (0) /home/alessio/anaconda3/lib/libxgboost.so(+0xc01d4) [0x7f0fa8cc01d4]\n  [bt] (1) /home/alessio/anaconda3/lib/libxgboost.so(+0x1aaf12) [0x7f0fa8daaf12]\n  [bt] (2) /home/alessio/anaconda3/lib/libxgboost.so(xgboost::gbm::GBTree::ConfigureUpdaters()+0xdd) [0x7f0fa8e62e9d]\n  [bt] (3) /home/alessio/anaconda3/lib/libxgboost.so(xgboost::gbm::GBTree::Configure(std::vector<std::pair<std::__cxx11::basic_string<char, std::char_traits<char>, std::allocator<char> >, std::__cxx11::basic_string<char, std::char_traits<char>, std::allocator<char> > >, std::allocator<std::pair<std::__cxx11::basic_string<char, std::char_traits<char>, std::allocator<char> >, std::__cxx11::basic_string<char, std::char_traits<char>, std::allocator<char> > > > > const&)+0x331) [0x7f0fa8e7a6d1]\n  [bt] (4) /home/alessio/anaconda3/lib/libxgboost.so(+0x2a7ab2) [0x7f0fa8ea7ab2]\n  [bt] (5) /home/alessio/anaconda3/lib/libxgboost.so(+0x29f6d7) [0x7f0fa8e9f6d7]\n  [bt] (6) /home/alessio/anaconda3/lib/libxgboost.so(XGBoosterUpdateOneIter+0x6c) [0x7f0fa8ccbfbc]\n  [bt] (7) /home/alessio/anaconda3/lib/python3.9/lib-dynload/../../libffi.so.7(+0x69dd) [0x7f0fe8b059dd]\n  [bt] (8) /home/alessio/anaconda3/lib/python3.9/lib-dynload/../../libffi.so.7(+0x6067) [0x7f0fe8b05067]\n\n\n\n--------------------------------------------------------------------------------\n1 fits failed with the following error:\nTraceback (most recent call last):\n  File \"/home/alessio/anaconda3/lib/python3.9/site-packages/sklearn/model_selection/_validation.py\", line 686, in _fit_and_score\n    estimator.fit(X_train, y_train, **fit_params)\n  File \"/home/alessio/anaconda3/lib/python3.9/site-packages/imblearn/pipeline.py\", line 297, in fit\n    self._final_estimator.fit(Xt, yt, **fit_params_last_step)\n  File \"/home/alessio/anaconda3/lib/python3.9/site-packages/xgboost/core.py\", line 620, in inner_f\n    return func(**kwargs)\n  File \"/home/alessio/anaconda3/lib/python3.9/site-packages/xgboost/sklearn.py\", line 1490, in fit\n    self._Booster = train(\n  File \"/home/alessio/anaconda3/lib/python3.9/site-packages/xgboost/core.py\", line 620, in inner_f\n    return func(**kwargs)\n  File \"/home/alessio/anaconda3/lib/python3.9/site-packages/xgboost/training.py\", line 185, in train\n    bst.update(dtrain, i, obj)\n  File \"/home/alessio/anaconda3/lib/python3.9/site-packages/xgboost/core.py\", line 1918, in update\n    _check_call(_LIB.XGBoosterUpdateOneIter(self.handle,\n  File \"/home/alessio/anaconda3/lib/python3.9/site-packages/xgboost/core.py\", line 279, in _check_call\n    raise XGBoostError(py_str(_LIB.XGBGetLastError()))\nxgboost.core.XGBoostError: [16:48:59] /croot/xgboost-split_1675457761144/work/src/data/../common/common.h:239: XGBoost version not compiled with GPU support.\nStack trace:\n  [bt] (0) /home/alessio/anaconda3/lib/libxgboost.so(+0xc01d4) [0x7f0fa8cc01d4]\n  [bt] (1) /home/alessio/anaconda3/lib/libxgboost.so(+0x1aaf12) [0x7f0fa8daaf12]\n  [bt] (2) /home/alessio/anaconda3/lib/libxgboost.so(xgboost::gbm::GBTree::ConfigureUpdaters()+0xdd) [0x7f0fa8e62e9d]\n  [bt] (3) /home/alessio/anaconda3/lib/libxgboost.so(xgboost::gbm::GBTree::Configure(std::vector<std::pair<std::__cxx11::basic_string<char, std::char_traits<char>, std::allocator<char> >, std::__cxx11::basic_string<char, std::char_traits<char>, std::allocator<char> > >, std::allocator<std::pair<std::__cxx11::basic_string<char, std::char_traits<char>, std::allocator<char> >, std::__cxx11::basic_string<char, std::char_traits<char>, std::allocator<char> > > > > const&)+0x331) [0x7f0fa8e7a6d1]\n  [bt] (4) /home/alessio/anaconda3/lib/libxgboost.so(+0x2a7ab2) [0x7f0fa8ea7ab2]\n  [bt] (5) /home/alessio/anaconda3/lib/libxgboost.so(+0x29f6d7) [0x7f0fa8e9f6d7]\n  [bt] (6) /home/alessio/anaconda3/lib/libxgboost.so(XGBoosterUpdateOneIter+0x6c) [0x7f0fa8ccbfbc]\n  [bt] (7) /home/alessio/anaconda3/lib/python3.9/lib-dynload/../../libffi.so.7(+0x69dd) [0x7f0fe8b059dd]\n  [bt] (8) /home/alessio/anaconda3/lib/python3.9/lib-dynload/../../libffi.so.7(+0x6067) [0x7f0fe8b05067]\n\n\n\n--------------------------------------------------------------------------------\n1 fits failed with the following error:\nTraceback (most recent call last):\n  File \"/home/alessio/anaconda3/lib/python3.9/site-packages/sklearn/model_selection/_validation.py\", line 686, in _fit_and_score\n    estimator.fit(X_train, y_train, **fit_params)\n  File \"/home/alessio/anaconda3/lib/python3.9/site-packages/imblearn/pipeline.py\", line 297, in fit\n    self._final_estimator.fit(Xt, yt, **fit_params_last_step)\n  File \"/home/alessio/anaconda3/lib/python3.9/site-packages/xgboost/core.py\", line 620, in inner_f\n    return func(**kwargs)\n  File \"/home/alessio/anaconda3/lib/python3.9/site-packages/xgboost/sklearn.py\", line 1490, in fit\n    self._Booster = train(\n  File \"/home/alessio/anaconda3/lib/python3.9/site-packages/xgboost/core.py\", line 620, in inner_f\n    return func(**kwargs)\n  File \"/home/alessio/anaconda3/lib/python3.9/site-packages/xgboost/training.py\", line 185, in train\n    bst.update(dtrain, i, obj)\n  File \"/home/alessio/anaconda3/lib/python3.9/site-packages/xgboost/core.py\", line 1918, in update\n    _check_call(_LIB.XGBoosterUpdateOneIter(self.handle,\n  File \"/home/alessio/anaconda3/lib/python3.9/site-packages/xgboost/core.py\", line 279, in _check_call\n    raise XGBoostError(py_str(_LIB.XGBGetLastError()))\nxgboost.core.XGBoostError: [16:49:45] /croot/xgboost-split_1675457761144/work/src/data/../common/common.h:239: XGBoost version not compiled with GPU support.\nStack trace:\n  [bt] (0) /home/alessio/anaconda3/lib/libxgboost.so(+0xc01d4) [0x7f0fa8cc01d4]\n  [bt] (1) /home/alessio/anaconda3/lib/libxgboost.so(+0x1aaf12) [0x7f0fa8daaf12]\n  [bt] (2) /home/alessio/anaconda3/lib/libxgboost.so(xgboost::gbm::GBTree::ConfigureUpdaters()+0xdd) [0x7f0fa8e62e9d]\n  [bt] (3) /home/alessio/anaconda3/lib/libxgboost.so(xgboost::gbm::GBTree::Configure(std::vector<std::pair<std::__cxx11::basic_string<char, std::char_traits<char>, std::allocator<char> >, std::__cxx11::basic_string<char, std::char_traits<char>, std::allocator<char> > >, std::allocator<std::pair<std::__cxx11::basic_string<char, std::char_traits<char>, std::allocator<char> >, std::__cxx11::basic_string<char, std::char_traits<char>, std::allocator<char> > > > > const&)+0x331) [0x7f0fa8e7a6d1]\n  [bt] (4) /home/alessio/anaconda3/lib/libxgboost.so(+0x2a7ab2) [0x7f0fa8ea7ab2]\n  [bt] (5) /home/alessio/anaconda3/lib/libxgboost.so(+0x29f6d7) [0x7f0fa8e9f6d7]\n  [bt] (6) /home/alessio/anaconda3/lib/libxgboost.so(XGBoosterUpdateOneIter+0x6c) [0x7f0fa8ccbfbc]\n  [bt] (7) /home/alessio/anaconda3/lib/python3.9/lib-dynload/../../libffi.so.7(+0x69dd) [0x7f0fe8b059dd]\n  [bt] (8) /home/alessio/anaconda3/lib/python3.9/lib-dynload/../../libffi.so.7(+0x6067) [0x7f0fe8b05067]\n\n\n\n--------------------------------------------------------------------------------\n1 fits failed with the following error:\nTraceback (most recent call last):\n  File \"/home/alessio/anaconda3/lib/python3.9/site-packages/sklearn/model_selection/_validation.py\", line 686, in _fit_and_score\n    estimator.fit(X_train, y_train, **fit_params)\n  File \"/home/alessio/anaconda3/lib/python3.9/site-packages/imblearn/pipeline.py\", line 297, in fit\n    self._final_estimator.fit(Xt, yt, **fit_params_last_step)\n  File \"/home/alessio/anaconda3/lib/python3.9/site-packages/xgboost/core.py\", line 620, in inner_f\n    return func(**kwargs)\n  File \"/home/alessio/anaconda3/lib/python3.9/site-packages/xgboost/sklearn.py\", line 1490, in fit\n    self._Booster = train(\n  File \"/home/alessio/anaconda3/lib/python3.9/site-packages/xgboost/core.py\", line 620, in inner_f\n    return func(**kwargs)\n  File \"/home/alessio/anaconda3/lib/python3.9/site-packages/xgboost/training.py\", line 185, in train\n    bst.update(dtrain, i, obj)\n  File \"/home/alessio/anaconda3/lib/python3.9/site-packages/xgboost/core.py\", line 1918, in update\n    _check_call(_LIB.XGBoosterUpdateOneIter(self.handle,\n  File \"/home/alessio/anaconda3/lib/python3.9/site-packages/xgboost/core.py\", line 279, in _check_call\n    raise XGBoostError(py_str(_LIB.XGBGetLastError()))\nxgboost.core.XGBoostError: [16:50:31] /croot/xgboost-split_1675457761144/work/src/data/../common/common.h:239: XGBoost version not compiled with GPU support.\nStack trace:\n  [bt] (0) /home/alessio/anaconda3/lib/libxgboost.so(+0xc01d4) [0x7f0fa8cc01d4]\n  [bt] (1) /home/alessio/anaconda3/lib/libxgboost.so(+0x1aaf12) [0x7f0fa8daaf12]\n  [bt] (2) /home/alessio/anaconda3/lib/libxgboost.so(xgboost::gbm::GBTree::ConfigureUpdaters()+0xdd) [0x7f0fa8e62e9d]\n  [bt] (3) /home/alessio/anaconda3/lib/libxgboost.so(xgboost::gbm::GBTree::Configure(std::vector<std::pair<std::__cxx11::basic_string<char, std::char_traits<char>, std::allocator<char> >, std::__cxx11::basic_string<char, std::char_traits<char>, std::allocator<char> > >, std::allocator<std::pair<std::__cxx11::basic_string<char, std::char_traits<char>, std::allocator<char> >, std::__cxx11::basic_string<char, std::char_traits<char>, std::allocator<char> > > > > const&)+0x331) [0x7f0fa8e7a6d1]\n  [bt] (4) /home/alessio/anaconda3/lib/libxgboost.so(+0x2a7ab2) [0x7f0fa8ea7ab2]\n  [bt] (5) /home/alessio/anaconda3/lib/libxgboost.so(+0x29f6d7) [0x7f0fa8e9f6d7]\n  [bt] (6) /home/alessio/anaconda3/lib/libxgboost.so(XGBoosterUpdateOneIter+0x6c) [0x7f0fa8ccbfbc]\n  [bt] (7) /home/alessio/anaconda3/lib/python3.9/lib-dynload/../../libffi.so.7(+0x69dd) [0x7f0fe8b059dd]\n  [bt] (8) /home/alessio/anaconda3/lib/python3.9/lib-dynload/../../libffi.so.7(+0x6067) [0x7f0fe8b05067]\n\n\n\n--------------------------------------------------------------------------------\n1 fits failed with the following error:\nTraceback (most recent call last):\n  File \"/home/alessio/anaconda3/lib/python3.9/site-packages/sklearn/model_selection/_validation.py\", line 686, in _fit_and_score\n    estimator.fit(X_train, y_train, **fit_params)\n  File \"/home/alessio/anaconda3/lib/python3.9/site-packages/imblearn/pipeline.py\", line 297, in fit\n    self._final_estimator.fit(Xt, yt, **fit_params_last_step)\n  File \"/home/alessio/anaconda3/lib/python3.9/site-packages/xgboost/core.py\", line 620, in inner_f\n    return func(**kwargs)\n  File \"/home/alessio/anaconda3/lib/python3.9/site-packages/xgboost/sklearn.py\", line 1490, in fit\n    self._Booster = train(\n  File \"/home/alessio/anaconda3/lib/python3.9/site-packages/xgboost/core.py\", line 620, in inner_f\n    return func(**kwargs)\n  File \"/home/alessio/anaconda3/lib/python3.9/site-packages/xgboost/training.py\", line 185, in train\n    bst.update(dtrain, i, obj)\n  File \"/home/alessio/anaconda3/lib/python3.9/site-packages/xgboost/core.py\", line 1918, in update\n    _check_call(_LIB.XGBoosterUpdateOneIter(self.handle,\n  File \"/home/alessio/anaconda3/lib/python3.9/site-packages/xgboost/core.py\", line 279, in _check_call\n    raise XGBoostError(py_str(_LIB.XGBGetLastError()))\nxgboost.core.XGBoostError: [16:51:18] /croot/xgboost-split_1675457761144/work/src/data/../common/common.h:239: XGBoost version not compiled with GPU support.\nStack trace:\n  [bt] (0) /home/alessio/anaconda3/lib/libxgboost.so(+0xc01d4) [0x7f0fa8cc01d4]\n  [bt] (1) /home/alessio/anaconda3/lib/libxgboost.so(+0x1aaf12) [0x7f0fa8daaf12]\n  [bt] (2) /home/alessio/anaconda3/lib/libxgboost.so(xgboost::gbm::GBTree::ConfigureUpdaters()+0xdd) [0x7f0fa8e62e9d]\n  [bt] (3) /home/alessio/anaconda3/lib/libxgboost.so(xgboost::gbm::GBTree::Configure(std::vector<std::pair<std::__cxx11::basic_string<char, std::char_traits<char>, std::allocator<char> >, std::__cxx11::basic_string<char, std::char_traits<char>, std::allocator<char> > >, std::allocator<std::pair<std::__cxx11::basic_string<char, std::char_traits<char>, std::allocator<char> >, std::__cxx11::basic_string<char, std::char_traits<char>, std::allocator<char> > > > > const&)+0x331) [0x7f0fa8e7a6d1]\n  [bt] (4) /home/alessio/anaconda3/lib/libxgboost.so(+0x2a7ab2) [0x7f0fa8ea7ab2]\n  [bt] (5) /home/alessio/anaconda3/lib/libxgboost.so(+0x29f6d7) [0x7f0fa8e9f6d7]\n  [bt] (6) /home/alessio/anaconda3/lib/libxgboost.so(XGBoosterUpdateOneIter+0x6c) [0x7f0fa8ccbfbc]\n  [bt] (7) /home/alessio/anaconda3/lib/python3.9/lib-dynload/../../libffi.so.7(+0x69dd) [0x7f0fe8b059dd]\n  [bt] (8) /home/alessio/anaconda3/lib/python3.9/lib-dynload/../../libffi.so.7(+0x6067) [0x7f0fe8b05067]\n\n\n\n--------------------------------------------------------------------------------\n1 fits failed with the following error:\nTraceback (most recent call last):\n  File \"/home/alessio/anaconda3/lib/python3.9/site-packages/sklearn/model_selection/_validation.py\", line 686, in _fit_and_score\n    estimator.fit(X_train, y_train, **fit_params)\n  File \"/home/alessio/anaconda3/lib/python3.9/site-packages/imblearn/pipeline.py\", line 297, in fit\n    self._final_estimator.fit(Xt, yt, **fit_params_last_step)\n  File \"/home/alessio/anaconda3/lib/python3.9/site-packages/xgboost/core.py\", line 620, in inner_f\n    return func(**kwargs)\n  File \"/home/alessio/anaconda3/lib/python3.9/site-packages/xgboost/sklearn.py\", line 1490, in fit\n    self._Booster = train(\n  File \"/home/alessio/anaconda3/lib/python3.9/site-packages/xgboost/core.py\", line 620, in inner_f\n    return func(**kwargs)\n  File \"/home/alessio/anaconda3/lib/python3.9/site-packages/xgboost/training.py\", line 185, in train\n    bst.update(dtrain, i, obj)\n  File \"/home/alessio/anaconda3/lib/python3.9/site-packages/xgboost/core.py\", line 1918, in update\n    _check_call(_LIB.XGBoosterUpdateOneIter(self.handle,\n  File \"/home/alessio/anaconda3/lib/python3.9/site-packages/xgboost/core.py\", line 279, in _check_call\n    raise XGBoostError(py_str(_LIB.XGBGetLastError()))\nxgboost.core.XGBoostError: [16:52:04] /croot/xgboost-split_1675457761144/work/src/data/../common/common.h:239: XGBoost version not compiled with GPU support.\nStack trace:\n  [bt] (0) /home/alessio/anaconda3/lib/libxgboost.so(+0xc01d4) [0x7f0fa8cc01d4]\n  [bt] (1) /home/alessio/anaconda3/lib/libxgboost.so(+0x1aaf12) [0x7f0fa8daaf12]\n  [bt] (2) /home/alessio/anaconda3/lib/libxgboost.so(xgboost::gbm::GBTree::ConfigureUpdaters()+0xdd) [0x7f0fa8e62e9d]\n  [bt] (3) /home/alessio/anaconda3/lib/libxgboost.so(xgboost::gbm::GBTree::Configure(std::vector<std::pair<std::__cxx11::basic_string<char, std::char_traits<char>, std::allocator<char> >, std::__cxx11::basic_string<char, std::char_traits<char>, std::allocator<char> > >, std::allocator<std::pair<std::__cxx11::basic_string<char, std::char_traits<char>, std::allocator<char> >, std::__cxx11::basic_string<char, std::char_traits<char>, std::allocator<char> > > > > const&)+0x331) [0x7f0fa8e7a6d1]\n  [bt] (4) /home/alessio/anaconda3/lib/libxgboost.so(+0x2a7ab2) [0x7f0fa8ea7ab2]\n  [bt] (5) /home/alessio/anaconda3/lib/libxgboost.so(+0x29f6d7) [0x7f0fa8e9f6d7]\n  [bt] (6) /home/alessio/anaconda3/lib/libxgboost.so(XGBoosterUpdateOneIter+0x6c) [0x7f0fa8ccbfbc]\n  [bt] (7) /home/alessio/anaconda3/lib/python3.9/lib-dynload/../../libffi.so.7(+0x69dd) [0x7f0fe8b059dd]\n  [bt] (8) /home/alessio/anaconda3/lib/python3.9/lib-dynload/../../libffi.so.7(+0x6067) [0x7f0fe8b05067]\n\n\n\n--------------------------------------------------------------------------------\n1 fits failed with the following error:\nTraceback (most recent call last):\n  File \"/home/alessio/anaconda3/lib/python3.9/site-packages/sklearn/model_selection/_validation.py\", line 686, in _fit_and_score\n    estimator.fit(X_train, y_train, **fit_params)\n  File \"/home/alessio/anaconda3/lib/python3.9/site-packages/imblearn/pipeline.py\", line 297, in fit\n    self._final_estimator.fit(Xt, yt, **fit_params_last_step)\n  File \"/home/alessio/anaconda3/lib/python3.9/site-packages/xgboost/core.py\", line 620, in inner_f\n    return func(**kwargs)\n  File \"/home/alessio/anaconda3/lib/python3.9/site-packages/xgboost/sklearn.py\", line 1490, in fit\n    self._Booster = train(\n  File \"/home/alessio/anaconda3/lib/python3.9/site-packages/xgboost/core.py\", line 620, in inner_f\n    return func(**kwargs)\n  File \"/home/alessio/anaconda3/lib/python3.9/site-packages/xgboost/training.py\", line 185, in train\n    bst.update(dtrain, i, obj)\n  File \"/home/alessio/anaconda3/lib/python3.9/site-packages/xgboost/core.py\", line 1918, in update\n    _check_call(_LIB.XGBoosterUpdateOneIter(self.handle,\n  File \"/home/alessio/anaconda3/lib/python3.9/site-packages/xgboost/core.py\", line 279, in _check_call\n    raise XGBoostError(py_str(_LIB.XGBGetLastError()))\nxgboost.core.XGBoostError: [16:52:50] /croot/xgboost-split_1675457761144/work/src/data/../common/common.h:239: XGBoost version not compiled with GPU support.\nStack trace:\n  [bt] (0) /home/alessio/anaconda3/lib/libxgboost.so(+0xc01d4) [0x7f0fa8cc01d4]\n  [bt] (1) /home/alessio/anaconda3/lib/libxgboost.so(+0x1aaf12) [0x7f0fa8daaf12]\n  [bt] (2) /home/alessio/anaconda3/lib/libxgboost.so(xgboost::gbm::GBTree::ConfigureUpdaters()+0xdd) [0x7f0fa8e62e9d]\n  [bt] (3) /home/alessio/anaconda3/lib/libxgboost.so(xgboost::gbm::GBTree::Configure(std::vector<std::pair<std::__cxx11::basic_string<char, std::char_traits<char>, std::allocator<char> >, std::__cxx11::basic_string<char, std::char_traits<char>, std::allocator<char> > >, std::allocator<std::pair<std::__cxx11::basic_string<char, std::char_traits<char>, std::allocator<char> >, std::__cxx11::basic_string<char, std::char_traits<char>, std::allocator<char> > > > > const&)+0x331) [0x7f0fa8e7a6d1]\n  [bt] (4) /home/alessio/anaconda3/lib/libxgboost.so(+0x2a7ab2) [0x7f0fa8ea7ab2]\n  [bt] (5) /home/alessio/anaconda3/lib/libxgboost.so(+0x29f6d7) [0x7f0fa8e9f6d7]\n  [bt] (6) /home/alessio/anaconda3/lib/libxgboost.so(XGBoosterUpdateOneIter+0x6c) [0x7f0fa8ccbfbc]\n  [bt] (7) /home/alessio/anaconda3/lib/python3.9/lib-dynload/../../libffi.so.7(+0x69dd) [0x7f0fe8b059dd]\n  [bt] (8) /home/alessio/anaconda3/lib/python3.9/lib-dynload/../../libffi.so.7(+0x6067) [0x7f0fe8b05067]\n\n\n\n--------------------------------------------------------------------------------\n1 fits failed with the following error:\nTraceback (most recent call last):\n  File \"/home/alessio/anaconda3/lib/python3.9/site-packages/sklearn/model_selection/_validation.py\", line 686, in _fit_and_score\n    estimator.fit(X_train, y_train, **fit_params)\n  File \"/home/alessio/anaconda3/lib/python3.9/site-packages/imblearn/pipeline.py\", line 297, in fit\n    self._final_estimator.fit(Xt, yt, **fit_params_last_step)\n  File \"/home/alessio/anaconda3/lib/python3.9/site-packages/xgboost/core.py\", line 620, in inner_f\n    return func(**kwargs)\n  File \"/home/alessio/anaconda3/lib/python3.9/site-packages/xgboost/sklearn.py\", line 1490, in fit\n    self._Booster = train(\n  File \"/home/alessio/anaconda3/lib/python3.9/site-packages/xgboost/core.py\", line 620, in inner_f\n    return func(**kwargs)\n  File \"/home/alessio/anaconda3/lib/python3.9/site-packages/xgboost/training.py\", line 185, in train\n    bst.update(dtrain, i, obj)\n  File \"/home/alessio/anaconda3/lib/python3.9/site-packages/xgboost/core.py\", line 1918, in update\n    _check_call(_LIB.XGBoosterUpdateOneIter(self.handle,\n  File \"/home/alessio/anaconda3/lib/python3.9/site-packages/xgboost/core.py\", line 279, in _check_call\n    raise XGBoostError(py_str(_LIB.XGBGetLastError()))\nxgboost.core.XGBoostError: [16:53:36] /croot/xgboost-split_1675457761144/work/src/data/../common/common.h:239: XGBoost version not compiled with GPU support.\nStack trace:\n  [bt] (0) /home/alessio/anaconda3/lib/libxgboost.so(+0xc01d4) [0x7f0fa8cc01d4]\n  [bt] (1) /home/alessio/anaconda3/lib/libxgboost.so(+0x1aaf12) [0x7f0fa8daaf12]\n  [bt] (2) /home/alessio/anaconda3/lib/libxgboost.so(xgboost::gbm::GBTree::ConfigureUpdaters()+0xdd) [0x7f0fa8e62e9d]\n  [bt] (3) /home/alessio/anaconda3/lib/libxgboost.so(xgboost::gbm::GBTree::Configure(std::vector<std::pair<std::__cxx11::basic_string<char, std::char_traits<char>, std::allocator<char> >, std::__cxx11::basic_string<char, std::char_traits<char>, std::allocator<char> > >, std::allocator<std::pair<std::__cxx11::basic_string<char, std::char_traits<char>, std::allocator<char> >, std::__cxx11::basic_string<char, std::char_traits<char>, std::allocator<char> > > > > const&)+0x331) [0x7f0fa8e7a6d1]\n  [bt] (4) /home/alessio/anaconda3/lib/libxgboost.so(+0x2a7ab2) [0x7f0fa8ea7ab2]\n  [bt] (5) /home/alessio/anaconda3/lib/libxgboost.so(+0x29f6d7) [0x7f0fa8e9f6d7]\n  [bt] (6) /home/alessio/anaconda3/lib/libxgboost.so(XGBoosterUpdateOneIter+0x6c) [0x7f0fa8ccbfbc]\n  [bt] (7) /home/alessio/anaconda3/lib/python3.9/lib-dynload/../../libffi.so.7(+0x69dd) [0x7f0fe8b059dd]\n  [bt] (8) /home/alessio/anaconda3/lib/python3.9/lib-dynload/../../libffi.so.7(+0x6067) [0x7f0fe8b05067]\n\n\n\n--------------------------------------------------------------------------------\n1 fits failed with the following error:\nTraceback (most recent call last):\n  File \"/home/alessio/anaconda3/lib/python3.9/site-packages/sklearn/model_selection/_validation.py\", line 686, in _fit_and_score\n    estimator.fit(X_train, y_train, **fit_params)\n  File \"/home/alessio/anaconda3/lib/python3.9/site-packages/imblearn/pipeline.py\", line 297, in fit\n    self._final_estimator.fit(Xt, yt, **fit_params_last_step)\n  File \"/home/alessio/anaconda3/lib/python3.9/site-packages/xgboost/core.py\", line 620, in inner_f\n    return func(**kwargs)\n  File \"/home/alessio/anaconda3/lib/python3.9/site-packages/xgboost/sklearn.py\", line 1490, in fit\n    self._Booster = train(\n  File \"/home/alessio/anaconda3/lib/python3.9/site-packages/xgboost/core.py\", line 620, in inner_f\n    return func(**kwargs)\n  File \"/home/alessio/anaconda3/lib/python3.9/site-packages/xgboost/training.py\", line 185, in train\n    bst.update(dtrain, i, obj)\n  File \"/home/alessio/anaconda3/lib/python3.9/site-packages/xgboost/core.py\", line 1918, in update\n    _check_call(_LIB.XGBoosterUpdateOneIter(self.handle,\n  File \"/home/alessio/anaconda3/lib/python3.9/site-packages/xgboost/core.py\", line 279, in _check_call\n    raise XGBoostError(py_str(_LIB.XGBGetLastError()))\nxgboost.core.XGBoostError: [16:54:21] /croot/xgboost-split_1675457761144/work/src/data/../common/common.h:239: XGBoost version not compiled with GPU support.\nStack trace:\n  [bt] (0) /home/alessio/anaconda3/lib/libxgboost.so(+0xc01d4) [0x7f0fa8cc01d4]\n  [bt] (1) /home/alessio/anaconda3/lib/libxgboost.so(+0x1aaf12) [0x7f0fa8daaf12]\n  [bt] (2) /home/alessio/anaconda3/lib/libxgboost.so(xgboost::gbm::GBTree::ConfigureUpdaters()+0xdd) [0x7f0fa8e62e9d]\n  [bt] (3) /home/alessio/anaconda3/lib/libxgboost.so(xgboost::gbm::GBTree::Configure(std::vector<std::pair<std::__cxx11::basic_string<char, std::char_traits<char>, std::allocator<char> >, std::__cxx11::basic_string<char, std::char_traits<char>, std::allocator<char> > >, std::allocator<std::pair<std::__cxx11::basic_string<char, std::char_traits<char>, std::allocator<char> >, std::__cxx11::basic_string<char, std::char_traits<char>, std::allocator<char> > > > > const&)+0x331) [0x7f0fa8e7a6d1]\n  [bt] (4) /home/alessio/anaconda3/lib/libxgboost.so(+0x2a7ab2) [0x7f0fa8ea7ab2]\n  [bt] (5) /home/alessio/anaconda3/lib/libxgboost.so(+0x29f6d7) [0x7f0fa8e9f6d7]\n  [bt] (6) /home/alessio/anaconda3/lib/libxgboost.so(XGBoosterUpdateOneIter+0x6c) [0x7f0fa8ccbfbc]\n  [bt] (7) /home/alessio/anaconda3/lib/python3.9/lib-dynload/../../libffi.so.7(+0x69dd) [0x7f0fe8b059dd]\n  [bt] (8) /home/alessio/anaconda3/lib/python3.9/lib-dynload/../../libffi.so.7(+0x6067) [0x7f0fe8b05067]\n\n\n\n--------------------------------------------------------------------------------\n1 fits failed with the following error:\nTraceback (most recent call last):\n  File \"/home/alessio/anaconda3/lib/python3.9/site-packages/sklearn/model_selection/_validation.py\", line 686, in _fit_and_score\n    estimator.fit(X_train, y_train, **fit_params)\n  File \"/home/alessio/anaconda3/lib/python3.9/site-packages/imblearn/pipeline.py\", line 297, in fit\n    self._final_estimator.fit(Xt, yt, **fit_params_last_step)\n  File \"/home/alessio/anaconda3/lib/python3.9/site-packages/xgboost/core.py\", line 620, in inner_f\n    return func(**kwargs)\n  File \"/home/alessio/anaconda3/lib/python3.9/site-packages/xgboost/sklearn.py\", line 1490, in fit\n    self._Booster = train(\n  File \"/home/alessio/anaconda3/lib/python3.9/site-packages/xgboost/core.py\", line 620, in inner_f\n    return func(**kwargs)\n  File \"/home/alessio/anaconda3/lib/python3.9/site-packages/xgboost/training.py\", line 185, in train\n    bst.update(dtrain, i, obj)\n  File \"/home/alessio/anaconda3/lib/python3.9/site-packages/xgboost/core.py\", line 1918, in update\n    _check_call(_LIB.XGBoosterUpdateOneIter(self.handle,\n  File \"/home/alessio/anaconda3/lib/python3.9/site-packages/xgboost/core.py\", line 279, in _check_call\n    raise XGBoostError(py_str(_LIB.XGBGetLastError()))\nxgboost.core.XGBoostError: [16:55:05] /croot/xgboost-split_1675457761144/work/src/data/../common/common.h:239: XGBoost version not compiled with GPU support.\nStack trace:\n  [bt] (0) /home/alessio/anaconda3/lib/libxgboost.so(+0xc01d4) [0x7f0fa8cc01d4]\n  [bt] (1) /home/alessio/anaconda3/lib/libxgboost.so(+0x1aaf12) [0x7f0fa8daaf12]\n  [bt] (2) /home/alessio/anaconda3/lib/libxgboost.so(xgboost::gbm::GBTree::ConfigureUpdaters()+0xdd) [0x7f0fa8e62e9d]\n  [bt] (3) /home/alessio/anaconda3/lib/libxgboost.so(xgboost::gbm::GBTree::Configure(std::vector<std::pair<std::__cxx11::basic_string<char, std::char_traits<char>, std::allocator<char> >, std::__cxx11::basic_string<char, std::char_traits<char>, std::allocator<char> > >, std::allocator<std::pair<std::__cxx11::basic_string<char, std::char_traits<char>, std::allocator<char> >, std::__cxx11::basic_string<char, std::char_traits<char>, std::allocator<char> > > > > const&)+0x331) [0x7f0fa8e7a6d1]\n  [bt] (4) /home/alessio/anaconda3/lib/libxgboost.so(+0x2a7ab2) [0x7f0fa8ea7ab2]\n  [bt] (5) /home/alessio/anaconda3/lib/libxgboost.so(+0x29f6d7) [0x7f0fa8e9f6d7]\n  [bt] (6) /home/alessio/anaconda3/lib/libxgboost.so(XGBoosterUpdateOneIter+0x6c) [0x7f0fa8ccbfbc]\n  [bt] (7) /home/alessio/anaconda3/lib/python3.9/lib-dynload/../../libffi.so.7(+0x69dd) [0x7f0fe8b059dd]\n  [bt] (8) /home/alessio/anaconda3/lib/python3.9/lib-dynload/../../libffi.so.7(+0x6067) [0x7f0fe8b05067]\n\n\n"
     ]
    }
   ],
   "source": [
    "# example of evaluating a decision tree with random undersampling\n",
    "from sklearn.model_selection import cross_validate\n",
    "from sklearn.model_selection import StratifiedKFold\n",
    "from xgboost import XGBClassifier\n",
    "from imblearn.pipeline import Pipeline\n",
    "from imblearn.under_sampling import RandomUnderSampler\n",
    "\n",
    "# define pipeline\n",
    "steps = [('under', RandomUnderSampler(sampling_strategy=0.03)), ('model', XGBClassifier(max_depth=6, learning_rate=0.3, tree_method='gpu_hist', gpu_id=1, verbosity = 2))]\n",
    "pipeline = Pipeline(steps=steps)\n",
    "# evaluate pipeline\n",
    "scoring = ['precision_macro', 'recall_macro', 'f1_macro', 'roc_auc']\n",
    "cv = StratifiedKFold(n_splits=10, random_state=42, shuffle=True)\n",
    "scores = cross_validate(pipeline, dummyDf, malwareColTrain, scoring=scoring, cv=cv)\n",
    "\n"
   ]
  },
  {
   "cell_type": "code",
   "execution_count": 20,
   "metadata": {
    "execution": {
     "iopub.execute_input": "2023-03-04T02:21:33.685121Z",
     "iopub.status.busy": "2023-03-04T02:21:33.684355Z",
     "iopub.status.idle": "2023-03-04T02:21:33.695346Z",
     "shell.execute_reply": "2023-03-04T02:21:33.693805Z",
     "shell.execute_reply.started": "2023-03-04T02:21:33.685121Z"
    }
   },
   "outputs": [
    {
     "name": "stdout",
     "output_type": "stream",
     "text": [
      "0.7930 accuracy\n",
      "0.9167 recall\n",
      "0.8424 f1 score\n",
      "0.9737 auc roc\n",
      "1.12315 training time\n",
      "0.30266 predition time\n"
     ]
    }
   ],
   "source": [
    "print(\"%0.4f accuracy\" % (scores['test_precision_macro'].mean()))\n",
    "print(\"%0.4f recall\" % (scores['test_recall_macro'].mean()))\n",
    "print(\"%0.4f f1 score\" % (scores['test_f1_macro'].mean()))\n",
    "print(\"%0.4f auc roc\" % (scores['test_roc_auc'].mean()))\n",
    "\n",
    "print(\"%0.5f training time\" % (scores['fit_time'].sum()))\n",
    "print(\"%0.5f predition time\" % (scores['score_time'].sum()))"
   ]
  }
 ],
 "metadata": {
  "interpreter": {
   "hash": "e7370f93d1d0cde622a1f8e1c04877d8463912d04d973331ad4851f04de6915a"
  },
  "kernelspec": {
   "display_name": "Python 3 (ipykernel)",
   "language": "python",
   "name": "python3"
  },
  "language_info": {
   "codemirror_mode": {
    "name": "ipython",
    "version": 3
   },
   "file_extension": ".py",
   "mimetype": "text/x-python",
   "name": "python",
   "nbconvert_exporter": "python",
   "pygments_lexer": "ipython3",
   "version": "3.9.7"
  }
 },
 "nbformat": 4,
 "nbformat_minor": 4
}
